Workbook

Sheet Sheet1
A1: 연번 | B1: 역번호 | C1: 종류 | D1: 종류번호 | E1: 역명 | F1: 코드 | G1: 위치 | H1: 연락처 | I1: 이미지 파일명
A2: =ROW()-1 -> 1 | B2: 211 | C2: ES | D2: 1 | E2: =VLOOKUP(B2,Sheet2!$G$2:$H$28,2,FALSE) -> 가정역 | F2: =B2&C2&TEXT(D2,"000") -> 211ES001 | G2: 에스컬레이터 1호기 | H2: 032-451-4311 | I2: =B2 -> 211
A3: =ROW()-1 -> 2 | B3: 211 | C3: ES | D3: 2 | E3: =VLOOKUP(B3,Sheet2!$G$2:$H$28,2,FALSE) -> 가정역 | F3: =B3&C3&TEXT(D3,"000") -> 211ES002 | G3: 에스컬레이터 2호기 | H3: 032-451-4311 | I3: =B3 -> 211
A4: =ROW()-1 -> 3 | B4: 211 | C4: ES | D4: 3 | E4: =VLOOKUP(B4,Sheet2!$G$2:$H$28,2,FALSE) -> 가정역 | F4: =B4&C4&TEXT(D4,"000") -> 211ES003 | G4: 에스컬레이터 3호기 | H4: 032-451-4311 | I4: =B4 -> 211
A5: =ROW()-1 -> 4 | B5: 211 | C5: ES | D5: 4 | E5: =VLOOKUP(B5,Sheet2!$G$2:$H$28,2,FALSE) -> 가정역 | F5: =B5&C5&TEXT(D5,"000") -> 211ES004 | G5: 에스컬레이터 4호기 | H5: 032-451-4311 | I5: =B5 -> 211
A6: =ROW()-1 -> 5 | B6: 211 | C6: ES | D6: 5 | E6: =VLOOKUP(B6,Sheet2!$G$2:$H$28,2,FALSE) -> 가정역 | F6: =B6&C6&TEXT(D6,"000") -> 211ES005 | G6: 에스컬레이터 5호기 | H6: 032-451-4311 | I6: =B6 -> 211
A7: =ROW()-1 -> 6 | B7: 211 | C7: ES | D7: 6 | E7: =VLOOKUP(B7,Sheet2!$G$2:$H$28,2,FALSE) -> 가정역 | F7: =B7&C7&TEXT(D7,"000") -> 211ES006 | G7: 에스컬레이터 6호기 | H7: 032-451-4311 | I7: =B7 -> 211
A8: =ROW()-1 -> 7 | B8: 211 | C8: ES | D8: 7 | E8: =VLOOKUP(B8,Sheet2!$G$2:$H$28,2,FALSE) -> 가정역 | F8: =B8&C8&TEXT(D8,"000") -> 211ES007 | G8: 에스컬레이터 7호기 | H8: 032-451-4311 | I8: =B8 -> 211
A9: =ROW()-1 -> 8 | B9: 211 | C9: ES | D9: 8 | E9: =VLOOKUP(B9,Sheet2!$G$2:$H$28,2,FALSE) -> 가정역 | F9: =B9&C9&TEXT(D9,"000") -> 211ES008 | G9: 에스컬레이터 8호기 | H9: 032-451-4311 | I9: =B9 -> 211
A10: =ROW()-1 -> 9 | B10: 211 | C10: ES | D10: 9 | E10: =VLOOKUP(B10,Sheet2!$G$2:$H$28,2,FALSE) -> 가정역 | F10: =B10&C10&TEXT(D10,"000") -> 211ES009 | G10: 에스컬레이터 9호기 | H10: 032-451-4311 | I10: =B10 -> 211
A11: =ROW()-1 -> 10 | B11: 211 | C11: ES | D11: 10 | E11: =VLOOKUP(B11,Sheet2!$G$2:$H$28,2,FALSE) -> 가정역 | F11: =B11&C11&TEXT(D11,"000") -> 211ES010 | G11: 에스컬레이터 10호기 | H11: 032-451-4311 | I11: =B11 -> 211
A12: =ROW()-1 -> 11 | B12: 211 | C12: ES | D12: 11 | E12: =VLOOKUP(B12,Sheet2!$G$2:$H$28,2,FALSE) -> 가정역 | F12: =B12&C12&TEXT(D12,"000") -> 211ES011 | G12: 에스컬레이터 11호기 | H12: 032-451-4311 | I12: =B12 -> 211
A13: =ROW()-1 -> 12 | B13: 211 | C13: ES | D13: 12 | E13: =VLOOKUP(B13,Sheet2!$G$2:$H$28,2,FALSE) -> 가정역 | F13: =B13&C13&TEXT(D13,"000") -> 211ES012 | G13: 에스컬레이터 12호기 | H13: 032-451-4311 | I13: =B13 -> 211
... A37: =ROW()-1 -> 36 | B37: 211 | C37: EXIT | D37: 8 | E37: =VLOOKUP(B37,Sheet2!$G$2:$H$28,2,FALSE) -> 가정역 | F37: =B37&C37&TEXT(D37,"000") -> 211EXIT008 | G37: 8번출구 | H37: 032-451-4311 | I37: =B37 -> 211
A38: =ROW()-1 -> 37 | B38: 211 | C38: TOILET | D38: 6M | E38: =VLOOKUP(B38,Sheet2!$G$2:$H$28,2,FALSE) -> 가정역 | F38: =B38&C38&TEXT(D38,"000") -> 211TOILET6M | G38: 6번출구 방면 남자화장실 | H38: 032-451-4311 | I38: =B38 -> 211
A39: =ROW()-1 -> 38 | B39: 211 | C39: TOILET | D39: 6W | E39: =VLOOKUP(B39,Sheet2!$G$2:$H$28,2,FALSE) -> 가정역 | F39: =B39&C39&TEXT(D39,"000") -> 211TOILET6W | G39: 6번출구 방면 여자화장실 | H39: 032-451-4311 | I39: =B39 -> 211
A40: =ROW()-1 -> 39 | B40: 211 | C40: TOILET | D40: 5M | E40: =VLOOKUP(B40,Sheet2!$G$2:$H$28,2,FALSE) -> 가정역 | F40: =B40&C40&TEXT(D40,"000") -> 211TOILET5M | G40: 5번출구 방면 남자화장실 | H40: 032-451-4311 | I40: =B40 -> 211
A41: =ROW()-1 -> 40 | B41: 211 | C41: TOILET | D41: 5W | E41: =VLOOKUP(B41,Sheet2!$G$2:$H$28,2,FALSE) -> 가정역 | F41: =B41&C41&TEXT(D41,"000") -> 211TOILET5W | G41: 5번출구 방면 여자화장실 | H41: 032-451-4311 | I41: =B41 -> 211
A42: =ROW()-1 -> 41 | B42: 211 | C42: UP | D42: FRONT | E42: =VLOOKUP(B42,Sheet2!$G$2:$H$28,2,FALSE) -> 가정역 | F42: =B42&C42&TEXT(D42,"000") -> 211UPFRONT | G42: 상선 전부(검단오류 방면) | H42: 032-451-4311 | I42: =B42 -> 211
A43: =ROW()-1 -> 42 | B43: 211 | C43: UP | D43: MID | E43: =VLOOKUP(B43,Sheet2!$G$2:$H$28,2,FALSE) -> 가정역 | F43: =B43&C43&TEXT(D43,"000") -> 211UPMID | G43: 상선 중앙(검단오류 방면) | H43: 032-451-4311 | I43: =B43 -> 211
A44: =ROW()-1 -> 43 | B44: 211 | C44: UP | D44: REAR | E44: =VLOOKUP(B44,Sheet2!$G$2:$H$28,2,FALSE) -> 가정역 | F44: =B44&C44&TEXT(D44,"000") -> 211UPREAR | G44: 상선 후부(검단오류 방면) | H44: 032-451-4311 | I44: =B44 -> 211
A45: =ROW()-1 -> 44 | B45: 211 | C45: DOWN | D45: FRONT | E45: =VLOOKUP(B45,Sheet2!$G$2:$H$28,2,FALSE) -> 가정역 | F45: =B45&C45&TEXT(D45,"000") -> 211DOWNFRONT | G45: 하선 전방(운연 방면) | H45: 032-451-4311 | I45: =B45 -> 211
A46: =ROW()-1 -> 45 | B46: 211 | C46: DOWN | D46: MID | E46: =VLOOKUP(B46,Sheet2!$G$2:$H$28,2,FALSE) -> 가정역 | F46: =B46&C46&TEXT(D46,"000") -> 211DOWNMID | G46: 하선 중앙(운연 방면) | H46: 032-451-4311 | I46: =B46 -> 211
A47: =ROW()-1 -> 46 | B47: 211 | C47: DOWN | D47: REAR | E47: =VLOOKUP(B47,Sheet2!$G$2:$H$28,2,FALSE) -> 가정역 | F47: =B47&C47&TEXT(D47,"000") -> 211DOWNREAR | G47: 하선 후부(운연 방면) | H47: 032-451-4311 | I47: =B47 -> 211
A48: =ROW()-1 -> 47 | B48: 211 | C48: STA | D48: 1 | E48: =VLOOKUP(B48,Sheet2!$G$2:$H$28,2,FALSE) -> 가정역 | F48: =B48&C48&TEXT(D48,"000") -> 211STA001 | G48: 대합실(1, 6, 7, 8번 출구 방면) | H48: 032-451-4311 | I48: =B48 -> 211
A49: =ROW()-1 -> 48 | B49: 211 | C49: STA | D49: 2 | E49: =VLOOKUP(B49,Sheet2!$G$2:$H$28,2,FALSE) -> 가정역 | F49: =B49&C49&TEXT(D49,"000") -> 211STA002 | G49: 대합실(2, 3, 4, 5번 출구 방면) | H49: 032-451-4311 | I49: =B49 -> 211
A50: =ROW()-1 -> 49 | B50: 209 | C50: ES | D50: 1 | E50: =VLOOKUP(B50,Sheet2!$G$2:$H$28,2,FALSE) -> 아시아드경기장역 | F50: =B50&C50&TEXT(D50,"000") -> 209ES001 | G50: 아시아드경기장역 에스컬레이터 1호기 | H50: 032-451-4309 | I50: =B50 -> 209
A51: =ROW()-1 -> 50 | B51: 209 | C51: ES | D51: 2 | E51: =VLOOKUP(B51,Sheet2!$G$2:$H$28,2,FALSE) -> 아시아드경기장역 | F51: =B51&C51&TEXT(D51,"000") -> 209ES002 | G51: 아시아드경기장역 에스컬레이터 2호기 | H51: 032-451-4309 | I51: =B51 -> 209
A52: =ROW()-1 -> 51 | B52: 209 | C52: ES | D52: 3 | E52: =VLOOKUP(B52,Sheet2!$G$2:$H$28,2,FALSE) -> 아시아드경기장역 | F52: =B52&C52&TEXT(D52,"000") -> 209ES003 | G52: 아시아드경기장역 에스컬레이터 3호기 | H52: 032-451-4309 | I52: =B52 -> 209
A53: =ROW()-1 -> 52 | B53: 209 | C53: ES | D53: 4 | E53: =VLOOKUP(B53,Sheet2!$G$2:$H$28,2,FALSE) -> 아시아드경기장역 | F53: =B53&C53&TEXT(D53,"000") -> 209ES004 | G53: 아시아드경기장역 에스컬레이터 4호기 | H53: 032-451-4309 | I53: =B53 -> 209
A54: =ROW()-1 -> 53 | B54: 209 | C54: ES | D54: 5 | E54: =VLOOKUP(B54,Sheet2!$G$2:$H$28,2,FALSE) -> 아시아드경기장역 | F54: =B54&C54&TEXT(D54,"000") -> 209ES005 | G54: 아시아드경기장역 에스컬레이터 5호기 | H54: 032-451-4309 | I54: =B54 -> 209
A55: =ROW()-1 -> 54 | B55: 209 | C55: ES | D55: 6 | E55: =VLOOKUP(B55,Sheet2!$G$2:$H$28,2,FALSE) -> 아시아드경기장역 | F55: =B55&C55&TEXT(D55,"000") -> 209ES006 | G55: 아시아드경기장역 에스컬레이터 6호기 | H55: 032-451-4309 | I55: =B55 -> 209
A56: =ROW()-1 -> 55 | B56: 209 | C56: ES | D56: 7 | E56: =VLOOKUP(B56,Sheet2!$G$2:$H$28,2,FALSE) -> 아시아드경기장역 | F56: =B56&C56&TEXT(D56,"000") -> 209ES007 | G56: 아시아드경기장역 에스컬레이터 7호기 | H56: 032-451-4309 | I56: =B56 -> 209
A57: =ROW()-1 -> 56 | B57: 209 | C57: ES | D57: 8 | E57: =VLOOKUP(B57,Sheet2!$G$2:$H$28,2,FALSE) -> 아시아드경기장역 | F57: =B57&C57&TEXT(D57,"000") -> 209ES008 | G57: 아시아드경기장역 에스컬레이터 8호기 | H57: 032-451-4309 | I57: =B57 -> 209
A58: =ROW()-1 -> 57 | B58: 209 | C58: TOILET | D58: 4M | E58: =VLOOKUP(B58,Sheet2!$G$2:$H$28,2,FALSE) -> 아시아드경기장역 | F58: =B58&C58&TEXT(D58,"000") -> 209TOILET4M | G58: 아시아드경기장역 4번 출구 방면 남자화장실 | H58: 032-451-4309 | I58: =B58 -> 209
A59: =ROW()-1 -> 58 | B59: 209 | C59: TOILET | D59: 4W | E59: =VLOOKUP(B59,Sheet2!$G$2:$H$28,2,FALSE) -> 아시아드경기장역 | F59: =B59&C59&TEXT(D59,"000") -> 209TOILET4W | G59: 아시아드경기장역 4번 출구 방면 여자화장실 | H59: 032-451-4309 | I59: =B59 -> 209
A60: =ROW()-1 -> 59 | B60: 209 | C60: EL | D60: 1 | E60: =VLOOKUP(B60,Sheet2!$G$2:$H$28,2,FALSE) -> 아시아드경기장역 | F60: =B60&C60&TEXT(D60,"000") -> 209EL001 | G60: 아시아드경기장역 엘리베이터 1호기(상선승강장) | H60: 032-451-4309 | I60: =B60 -> 209
A61: =ROW()-1 -> 60 | B61: 209 | C61: EL | D61: 2 | E61: =VLOOKUP(B61,Sheet2!$G$2:$H$28,2,FALSE) -> 아시아드경기장역 | F61: =B61&C61&TEXT(D61,"000") -> 209EL002 | G61: 아시아드경기장역 엘리베이터 2호기(하선승강장) | H61: 032-451-4309 | I61: =B61 -> 209
A62: =ROW()-1 -> 61 | B62: 209 | C62: EL | D62: 3 | E62: =VLOOKUP(B62,Sheet2!$G$2:$H$28,2,FALSE) -> 아시아드경기장역 | F62: =B62&C62&TEXT(D62,"000") -> 209EL003 | G62: 아시아드경기장역 엘리베이터 3호기(1, 2번 출구) | H62: 032-451-4309 | I62: =B62 -> 209
A63: =ROW()-1 -> 62 | B63: 209 | C63: EL | D63: 4 | E63: =VLOOKUP(B63,Sheet2!$G$2:$H$28,2,FALSE) -> 아시아드경기장역 | F63: =B63&C63&TEXT(D63,"000") -> 209EL004 | G63: 아시아드경기장역 엘리베이터 4호기(3, 4번 출구) | H63: 032-451-4309 | I63: =B63 -> 209
...

Sheet Sheet2
A1: 역이름 | B1: 코드 | C1: 위치 | D1: 연락처 | E1: 구역코드 | G1: 역명 VLOOKUP용
A2: 가정역 | B2: 211ES001 | C2: 에스컬레이터 1호기 | D2: 032-451-4311 | E2: 211ZONE08 | G2: 201 | H2: 검단오류역
A3: 가정역 | B3: 211ES002 | C3: 에스컬레이터 2호기 | D3: 032-451-4311 | E3: 211ZONE14 | G3: 202 | H3: 왕길역
A4: 가정역 | B4: 211ES003 | C4: 에스컬레이터 3호기 | D4: 032-451-4311 | E4: 211ZONE07 | G4: 203 | H4: 검단사거리역
A5: 가정역 | B5: 211ES004 | C5: 에스컬레이터 4호기 | D5: 032-451-4311 | E5: 211ZONE12 | G5: 204 | H5: 마전역
A6: 가정역 | B6: 211ES005 | C6: 에스컬레이터 5호기 | D6: 032-451-4311 | E6: 211ZONE07 | G6: 205 | H6: 완정역
A7: 가정역 | B7: 211ES006 | C7: 에스컬레이터 6호기 | D7: 032-451-4311 | E7: 211ZONE09 | G7: 206 | H7: 독정역
A8: 가정역 | B8: 211ES007 | C8: 에스컬레이터 7호기 | D8: 032-451-4311 | E8: 211ZONE08 | G8: 207 | H8: 검암역
A9: 가정역 | B9: 211ES008 | C9: 에스컬레이터 8호기 | D9: 032-451-4311 | E9: 211ZONE11 | G9: 208 | H9: 검바위역
A10: 가정역 | B10: 211ES009 | C10: 에스컬레이터 9호기 | D10: 032-451-4311 | E10: 211ZONE08 | G10: 209 | H10: 아시아드경기장역
A11: 가정역 | B11: 211ES010 | C11: 에스컬레이터 10호기 | D11: 032-451-4311 | E11: 211ZONE08 | G11: 210 | H11: 서해구청역
A12: 가정역 | B12: 211ES011 | C12: 에스컬레이터 11호기 | D12: 032-451-4311 | E12: 211ZONE07 | G12: 211 | H12: 가정역
A13: 가정역 | B13: 211ES012 | C13: 에스컬레이터 12호기 | D13: 032-451-4311 | E13: 211ZONE07 | G13: 212 | H13: 가정중앙시장역
... A28: 가정역 | B28: 211EL009 | C28: 엘리베이터 3호기(B3) | D28: 032-451-4311 | E28: 211ZONE10 | G28: 227 | H28: 운연역
A29: 가정역 | B29: 211EL010 | C29: 엘리베이터 4호기(B3) | D29: 032-451-4311 | E29: 211ZONE10
A30: 가정역 | B30: 211EXIT001 | C30: 1번출구 | D30: 032-451-4311 | E30: 211ZONE03
A31: 가정역 | B31: 211EXIT002 | C31: 2번출구 | D31: 032-451-4311 | E31: 211ZONE06
A32: 가정역 | B32: 211EXIT003 | C32: 3번출구 | D32: 032-451-4311 | E32: 211ZONE06
A33: 가정역 | B33: 211EXIT004 | C33: 4번출구 | D33: 032-451-4311 | E33: 211ZONE04
A34: 가정역 | B34: 211EXIT005 | C34: 5번출구 | D34: 032-451-4311 | E34: 211ZONE04
A35: 가정역 | B35: 211EXIT006 | C35: 6번출구 | D35: 032-451-4311 | E35: 211ZONE01
A36: 가정역 | B36: 211EXIT007 | C36: 7번출구 | D36: 032-451-4311 | E36: 211ZONE01
A37: 가정역 | B37: 211EXIT008 | C37: 8번출구 | D37: 032-451-4311 | E37: 211ZONE03
A38: 가정역 | B38: 211TOILET6M | C38: 6번출구 방면 남자화장실 | D38: 032-451-4311 | E38: 211ZONE01
A39: 가정역 | B39: 211TOILET6W | C39: 6번출구 방면 여자화장실 | D39: 032-451-4311 | E39: 211ZONE01
A40: 가정역 | B40: 211TOILET5M | C40: 5번출구 방면 남자화장실 | D40: 032-451-4311 | E40: 211ZONE04
... A82: 가정중앙시장역 | B82: 212EXIT002 | C82: 가정중앙시장역 2번 출구 | D82: 032-451-4312 | E82: 212ZONE01
